Workbook

Sheet Robots
B2: Nr. | C2: Robot name | D2: G1 | E2: G2 | F2: SK1 | G2: SK2 | H2: SK3 | I2: KW | J2: BZ1 | K2: BZ2 | L2: LM1 | M2: LM2 | N2: KL1 | O2: KL2 | P2: KL3 | Q2: LZ1 | R2: R | S2: DK | T2: BU | U2: CZ1 | V2: CZ2 | W2: … | Y2: Legend:
B3: 1 | C3: 112902R01 | D3: X | Y3: G | Z3: Gripper
B4: 2 | C4: 112905R01 | D4: X | F4: X | I4: X | Y4: SK | Z4: Weld
B5: 3 | C5: 112910R01 | F5: X | I5: X | Y5: BZ | Z5: Stud
B6: 4 | C6: 112915R01 | D6: X | F6: X | I6: X | Y6: LM | Z6: Measure
B7: 5 | C7: 112925R01 | D7: X | F7: X | I7: X | Y7: KL | Z7: Dispense
B8: 6 | C8: 112932R01 | D8: X | Y8: LZ | Z8: Laser
B9: 7 | C9: 112935R01 | D9: X | F9: X | I9: X | Y9: R | Z9: Heaming
B10: 8 | Y10: DK | Z10: Docking
B11: 9 | Y11: BU | Z11: Grinder
B12: 10 | Y12: CZ | Z12: Clinch
B13: 11 | Y13: KW | Z13: Tip Change
B14: 12
B15: 13
B16: 14
B17: 15
B18: 16
B19: 17
B20: 18
B21: 19
B22: 20
B23: 99 | C23: Extern | D23: n/a | E23: n/a | F23: n/a | G23: n/a | H23: n/a | I23: n/a | J23: n/a | K23: n/a | L23: n/a | M23: n/a | N23: n/a | O23: n/a | P23: n/a | Q23: n/a | R23: n/a | S23: n/a | T23: n/a | U23: n/a | V23: n/a | W23: n/a

Sheet 213560R01
A1: Robot | B1: 213560R01
I2: Robot inputs from PLC | L2: Robot outputs to PLC | Q2: Interlocks
A3: Folge | B3: Description | D3: Typ | E3: Description | G3: Release | H3: I/O | I3: Type | J3: Descrição | K3: I/O | L3: Type | M3: Description | N3: ST | O3: Device Nº | Q3: nº | R3: E/A | S3: 2 | T3: 3 | U3: 4 | V3: 5
A4: 1 | B4: VW427 | G4: 1 | H4: 80 | I4: LIB | J4: soldadura | K4: 80 | L4: PF1 | M4: mov geral | N4: 213560 | O4: 1 | S4: 213560R02 | T4: 213570R01 | U4: 213580R01 | V4: 213580R02
G5: 2 | H5: 79 | K5: 79 | Q5: 1 | R5: 41
G6: 3 | H6: 78 | K6: 78 | Q6: 2 | R6: 42
G7: 4 | H7: 77 | K7: 77 | Q7: 3 | R7: 43
G8: 5 | H8: 76 | K8: 76 | Q8: 4 | R8: 44
G9: 6 | H9: 75 | K9: 75 | Q9: 5 | R9: 45
G10: 7 | H10: 74 | K10: 74 | Q10: 6 | R10: 46
G11: 8 | H11: 73 | K11: 73 | Q11: 7 | R11: 47
G12: 9 | H12: 72 | K12: 72 | Q12: 8 | R12: 48
G13: 10 | H13: 71 | K13: 71 | Q13: 9 | R13: 49
G14: 11 | H14: 70 | K14: 70 | Q14: 10 | R14: 50
G15: 12 | H15: 69 | K15: 69 | Q15: 11 | R15: 51
G16: 13 | H16: 68 | K16: 68 | Q16: 12 | R16: 52
... G20: 17 | H20: 64 | K20: 64 | Q20: 16 | R20: 56
G21: 18 | H21: 63 | K21: 63
G22: 19 | H22: 62 | K22: 62
G23: 20 | H23: 61 | K23: 61 | Q23: Machine Safety
G24: 21 | H24: 60 | K24: 60 | Q24: 213560R02 | R24: X
G25: 22 | H25: 59 | K25: 59 | Q25: 213570R01 | R25: X
G26: 23 | H26: 58 | K26: 58 | Q26: 213580R01
G27: 24 | H27: 57 | K27: 57 | Q27: 213580R02
Q28: =IF(Robots!Q28<>0,Robots!Q28,"")
D29: FM | E29: Description | Q29: =IF(Robots!Q29<>0,Robots!Q29,"")
D30: 1 | E30: soldadura estacion 213560 | Q30: =IF(Robots!Q30<>0,Robots!Q30,"")
D31: 2 | Q31: =IF(Robots!Q31<>0,Robots!Q31,"")
D32: 3 | Q32: =IF(Robots!Q32<>0,Robots!Q32,"")
D33: 4 | Q33: =IF(Robots!Q33<>0,Robots!Q33,"")
D34: 5 | Q34: =IF(Robots!Q34<>0,Robots!Q34,"")
D35: 6 | Q35: =IF(Robots!Q35<>0,Robots!Q35,"")
D36: 7 | Q36: =IF(Robots!Q36<>0,Robots!Q36,"")
D37: 8 | Q37: =IF(Robots!Q37<>0,Robots!Q37,"")
D38: 9 | Q38: =IF(Robots!Q38<>0,Robots!Q38,"")
D39: 10 | Q39: =IF(Robots!Q39<>0,Robots!Q39,"")
D40: 11 | Q40: =IF(Robots!Q40<>0,Robots!Q40,"")
D41: 12 | Q41: =IF(Robots!Q41<>0,Robots!Q41,"")
D42: 13 | Q42: =IF(Robots!Q42<>0,Robots!Q42,"")
D43: 14 | Q43: =IF(Robots!Q43<>0,Robots!Q43,"")
...

Sheet 213560R02
A1: Robot | B1: 213560R02
I2: Robot inputs from PLC | L2: Robot outputs to PLC | Q2: Interlocks
A3: Folge | B3: Description | D3: Typ | E3: Description | G3: Release | H3: I/O | I3: Type | J3: Descrição | K3: I/O | L3: Type | M3: Description | N3: ST | O3: Device Nº | Q3: nº | R3: E/A | S3: 1 | T3: 3 | U3: 4 | V3: 5
A4: 1 | B4: VW427 | G4: 1 | H4: 80 | I4: LIB | J4: soldadura | K4: 80 | L4: PF1 | M4: mov geral | N4: 213560 | O4: 1 | S4: 213560R01 | T4: 213570R01 | U4: 213580R01 | V4: 213580R02
G5: 2 | H5: 79 | K5: 79 | Q5: 1 | R5: 41
G6: 3 | H6: 78 | K6: 78 | Q6: 2 | R6: 42
G7: 4 | H7: 77 | K7: 77 | Q7: 3 | R7: 43
G8: 5 | H8: 76 | K8: 76 | Q8: 4 | R8: 44
G9: 6 | H9: 75 | K9: 75 | Q9: 5 | R9: 45
G10: 7 | H10: 74 | K10: 74 | Q10: 6 | R10: 46
G11: 8 | H11: 73 | K11: 73 | Q11: 7 | R11: 47
G12: 9 | H12: 72 | K12: 72 | Q12: 8 | R12: 48
G13: 10 | H13: 71 | K13: 71 | Q13: 9 | R13: 49
G14: 11 | H14: 70 | K14: 70 | Q14: 10 | R14: 50
G15: 12 | H15: 69 | K15: 69 | Q15: 11 | R15: 51
G16: 13 | H16: 68 | K16: 68 | Q16: 12 | R16: 52
... G20: 17 | H20: 64 | K20: 64 | Q20: 16 | R20: 56
G21: 18 | H21: 63 | K21: 63
G22: 19 | H22: 62 | K22: 62
G23: 20 | H23: 61 | K23: 61 | Q23: Machine Safety
G24: 21 | H24: 60 | K24: 60 | Q24: 213560R01 | R24: X
G25: 22 | H25: 59 | K25: 59 | Q25: 213570R01 | R25: X
G26: 23 | H26: 58 | K26: 58 | Q26: 213580R01
G27: 24 | H27: 57 | K27: 57 | Q27: 213580R02
Q28: =IF(Robots!Q28<>0,Robots!Q28,"")
D29: FM | E29: Description | Q29: =IF(Robots!Q29<>0,Robots!Q29,"")
D30: 1 | E30: soldadura estacion 213560 | Q30: =IF(Robots!Q30<>0,Robots!Q30,"")
D31: 2 | Q31: =IF(Robots!Q31<>0,Robots!Q31,"")
D32: 3 | Q32: =IF(Robots!Q32<>0,Robots!Q32,"")
D33: 4 | Q33: =IF(Robots!Q33<>0,Robots!Q33,"")
D34: 5 | Q34: =IF(Robots!Q34<>0,Robots!Q34,"")
D35: 6 | Q35: =IF(Robots!Q35<>0,Robots!Q35,"")
D36: 7 | Q36: =IF(Robots!Q36<>0,Robots!Q36,"")
D37: 8 | Q37: =IF(Robots!Q37<>0,Robots!Q37,"")
D38: 9 | Q38: =IF(Robots!Q38<>0,Robots!Q38,"")
D39: 10 | Q39: =IF(Robots!Q39<>0,Robots!Q39,"")
D40: 11 | Q40: =IF(Robots!Q40<>0,Robots!Q40,"")
D41: 12 | Q41: =IF(Robots!Q41<>0,Robots!Q41,"")
D42: 13 | Q42: =IF(Robots!Q42<>0,Robots!Q42,"")
D43: 14 | Q43: =IF(Robots!Q43<>0,Robots!Q43,"")
...

Sheet 213570R01
A1: Robot | B1: 213570R01
I2: Robot inputs from PLC | L2: Robot outputs to PLC | Q2: Interlocks
A3: Folge | B3: Description | D3: Typ | E3: Description | G3: Release | H3: I/O | I3: Type | J3: Descrição | K3: I/O | L3: Type | M3: Description | N3: ST | O3: Device Nº | Q3: nº | R3: E/A | S3: 1 | T3: 2 | U3: 4 | V3: 5
A4: 1 | B4: VW427 | G4: 1 | H4: 80 | I4: LIB | J4: busca | K4: 80 | L4: PF1 | M4: mov. Geral | N4: 213565 | O4: 1 | S4: 213560R01 | T4: 213560R02 | U4: 213580R01 | V4: 213580R02
G5: 2 | H5: 79 | K5: 79 | Q5: 1 | R5: 41
G6: 3 | H6: 78 | K6: 78 | L6: POS1 | M6: posición de agarre | N6: 213565 | O6: 1 | Q6: 2 | R6: 42
G7: 4 | H7: 77 | I7: LIB | J7: deposita | K7: 77 | L7: PF1 | M7: mov. Geral | N7: 213560 | O7: 2 | Q7: 3 | R7: 43
G8: 5 | H8: 76 | K8: 76 | L8: PF2 | M8: mov Brida | Q8: 4 | R8: 44
G9: 6 | H9: 75 | K9: 75 | L9: POS1 | M9: depósito | N9: 213560 | O9: 2 | Q9: 5 | R9: 45
G10: 7 | H10: 74 | I10: LIB | J10: busca | K10: 74 | L10: PF3 | M10: mov. Brida | N10: 213560 | O10: 2 | Q10: 6 | R10: 46
G11: 8 | H11: 73 | K11: 73 | Q11: 7 | R11: 47
G12: 9 | H12: 72 | K12: 72 | L12: POS2 | M12: posición de agarre | N12: 213560 | O12: 2 | Q12: 8 | R12: 48
G13: 10 | H13: 71 | I13: LIB | J13: deposita | K13: 71 | L13: PF1 | M13: mov. Geral | N13: 213580 | O13: 3 | Q13: 9 | R13: 49
G14: 11 | H14: 70 | K14: 70 | L14: PF2 | M14: mov. Brida | Q14: 10 | R14: 50
G15: 12 | H15: 69 | K15: 69 | L15: POS1 | M15: depósito | N15: 213580 | O15: 3 | Q15: 11 | R15: 51
G16: 13 | H16: 68 | K16: 68 | Q16: 12 | R16: 52
G17: 14 | H17: 67 | K17: 67 | Q17: 13 | R17: 53
G18: 15 | H18: 66 | K18: 66 | Q18: 14 | R18: 54
G19: 16 | H19: 65 | K19: 65 | Q19: 15 | R19: 55
G20: 17 | H20: 64 | I20: KT | J20: 213565 ocupada | K20: 64 | Q20: 16 | R20: 56
G21: 18 | H21: 63 | I21: /KT | J21: 213565 libre | K21: 63
G22: 19 | H22: 62 | I22: KT | J22: 213560 ocupada | K22: 62
G23: 20 | H23: 61 | I23: /KT | J23: 213560 libre | K23: 61 | Q23: Machine Safety
G24: 21 | H24: 60 | I24: KT | J24: 213580 ocupada | K24: 60 | Q24: 213560R01 | R24: X
G25: 22 | H25: 59 | I25: /KT | J25: 213580 libre | K25: 59 | Q25: 213560R02 | R25: X
G26: 23 | H26: 58 | K26: 58 | Q26: 213580R01 | R26: X
G27: 24 | H27: 57 | K27: 57 | Q27: 213580R02 | R27: X
Q28: =IF(Robots!Q28<>0,Robots!Q28,"")
D29: FM | E29: Description | Q29: =IF(Robots!Q29<>0,Robots!Q29,"")
D30: 1 | E30: Coger Pieza Pos1 213565 | Q30: =IF(Robots!Q30<>0,Robots!Q30,"")
D31: 2 | E31: Dejar Pieza Pos2 213560 | Q31: =IF(Robots!Q31<>0,Robots!Q31,"")
D32: 3 | E32: Coger Pieza Pos1 213560 | Q32: =IF(Robots!Q32<>0,Robots!Q32,"")
D33: 4 | E33: Dejar Pieza Pos2 213580 | Q33: =IF(Robots!Q33<>0,Robots!Q33,"")
D34: 5 | Q34: =IF(Robots!Q34<>0,Robots!Q34,"")
D35: 6 | Q35: =IF(Robots!Q35<>0,Robots!Q35,"")
D36: 7 | Q36: =IF(Robots!Q36<>0,Robots!Q36,"")
D37: 8 | Q37: =IF(Robots!Q37<>0,Robots!Q37,"")
D38: 9 | Q38: =IF(Robots!Q38<>0,Robots!Q38,"")
D39: 10 | Q39: =IF(Robots!Q39<>0,Robots!Q39,"")
D40: 11 | Q40: =IF(Robots!Q40<>0,Robots!Q40,"")
...

Sheet 213580R01
A1: Robot | B1: 213580R01
I2: Robot inputs from PLC | L2: Robot outputs to PLC | Q2: Interlocks
A3: Folge | B3: Description | D3: Typ | E3: Description | G3: Release | H3: I/O | I3: Type | J3: Descrição | K3: I/O | L3: Type | M3: Description | N3: ST | O3: Device Nº | Q3: nº | R3: E/A | S3: 1 | T3: 2 | U3: 3 | V3: 5
A4: 1 | B4: VW427 | G4: 1 | H4: 80 | I4: LIB | J4: soldadura | K4: 80 | L4: PF1 | M4: mov geral | N4: 213580 | O4: 1 | S4: 213560R01 | T4: 213560R02 | U4: 213570R01 | V4: 213580R02
G5: 2 | H5: 79 | K5: 79 | Q5: 1 | R5: 41
G6: 3 | H6: 78 | K6: 78 | Q6: 2 | R6: 42
G7: 4 | H7: 77 | K7: 77 | Q7: 3 | R7: 43
G8: 5 | H8: 76 | K8: 76 | Q8: 4 | R8: 44
G9: 6 | H9: 75 | K9: 75 | Q9: 5 | R9: 45
G10: 7 | H10: 74 | K10: 74 | Q10: 6 | R10: 46
G11: 8 | H11: 73 | K11: 73 | Q11: 7 | R11: 47
G12: 9 | H12: 72 | K12: 72 | Q12: 8 | R12: 48
G13: 10 | H13: 71 | K13: 71 | Q13: 9 | R13: 49
G14: 11 | H14: 70 | K14: 70 | Q14: 10 | R14: 50
G15: 12 | H15: 69 | K15: 69 | Q15: 11 | R15: 51
G16: 13 | H16: 68 | K16: 68 | Q16: 12 | R16: 52
... G20: 17 | H20: 64 | K20: 64 | Q20: 16 | R20: 56
G21: 18 | H21: 63 | K21: 63
G22: 19 | H22: 62 | K22: 62
G23: 20 | H23: 61 | K23: 61 | Q23: Machine Safety
G24: 21 | H24: 60 | K24: 60 | Q24: 213560R01
G25: 22 | H25: 59 | K25: 59 | Q25: 213560R02
G26: 23 | H26: 58 | K26: 58 | Q26: 213570R01 | R26: X
G27: 24 | H27: 57 | K27: 57 | Q27: 213580R02 | R27: X
Q28: =IF(Robots!Q28<>0,Robots!Q28,"")
D29: FM | E29: Description | Q29: =IF(Robots!Q29<>0,Robots!Q29,"")
D30: 1 | E30: soldadura estacion 213580 | Q30: =IF(Robots!Q30<>0,Robots!Q30,"")
D31: 2 | Q31: =IF(Robots!Q31<>0,Robots!Q31,"")
D32: 3 | Q32: =IF(Robots!Q32<>0,Robots!Q32,"")
D33: 4 | Q33: =IF(Robots!Q33<>0,Robots!Q33,"")
D34: 5 | Q34: =IF(Robots!Q34<>0,Robots!Q34,"")
D35: 6 | Q35: =IF(Robots!Q35<>0,Robots!Q35,"")
D36: 7 | Q36: =IF(Robots!Q36<>0,Robots!Q36,"")
D37: 8 | Q37: =IF(Robots!Q37<>0,Robots!Q37,"")
D38: 9 | Q38: =IF(Robots!Q38<>0,Robots!Q38,"")
D39: 10 | Q39: =IF(Robots!Q39<>0,Robots!Q39,"")
D40: 11 | Q40: =IF(Robots!Q40<>0,Robots!Q40,"")
D41: 12 | Q41: =IF(Robots!Q41<>0,Robots!Q41,"")
D42: 13 | Q42: =IF(Robots!Q42<>0,Robots!Q42,"")
D43: 14 | Q43: =IF(Robots!Q43<>0,Robots!Q43,"")
...

Sheet 213580R02
A1: Robot | B1: 213580R02
I2: Robot inputs from PLC | L2: Robot outputs to PLC | Q2: Interlocks
A3: Folge | B3: Description | D3: Typ | E3: Description | G3: Release | H3: I/O | I3: Type | J3: Descrição | K3: I/O | L3: Type | M3: Description | N3: ST | O3: Device Nº | Q3: nº | R3: E/A | S3: 1 | T3: 2 | U3: 3 | V3: 4
A4: 1 | B4: VW427 | G4: 1 | H4: 80 | I4: LIB | J4: soldadura | K4: 80 | L4: PF1 | M4: mov geral | N4: 213580 | O4: 1 | S4: 213560R01 | T4: 213560R02 | U4: 213570R01 | V4: 213580R01
G5: 2 | H5: 79 | K5: 79 | Q5: 1 | R5: 41
G6: 3 | H6: 78 | K6: 78 | Q6: 2 | R6: 42
G7: 4 | H7: 77 | K7: 77 | Q7: 3 | R7: 43
G8: 5 | H8: 76 | K8: 76 | Q8: 4 | R8: 44
G9: 6 | H9: 75 | K9: 75 | Q9: 5 | R9: 45
G10: 7 | H10: 74 | K10: 74 | Q10: 6 | R10: 46
G11: 8 | H11: 73 | K11: 73 | Q11: 7 | R11: 47
G12: 9 | H12: 72 | K12: 72 | Q12: 8 | R12: 48
G13: 10 | H13: 71 | K13: 71 | Q13: 9 | R13: 49
G14: 11 | H14: 70 | K14: 70 | Q14: 10 | R14: 50
G15: 12 | H15: 69 | K15: 69 | Q15: 11 | R15: 51
G16: 13 | H16: 68 | K16: 68 | Q16: 12 | R16: 52
... G20: 17 | H20: 64 | K20: 64 | Q20: 16 | R20: 56
G21: 18 | H21: 63 | K21: 63
G22: 19 | H22: 62 | K22: 62
G23: 20 | H23: 61 | K23: 61 | Q23: Machine Safety
G24: 21 | H24: 60 | K24: 60 | Q24: 213560R01
G25: 22 | H25: 59 | K25: 59 | Q25: 213560R02
G26: 23 | H26: 58 | K26: 58 | Q26: 213570R01 | R26: X
G27: 24 | H27: 57 | K27: 57 | Q27: 213580R01 | R27: X
Q28: =IF(Robots!Q28<>0,Robots!Q28,"")
D29: FM | E29: Description | Q29: =IF(Robots!Q29<>0,Robots!Q29,"")
D30: 1 | E30: soldadura estacion 213580 | Q30: =IF(Robots!Q30<>0,Robots!Q30,"")
D31: 2 | Q31: =IF(Robots!Q31<>0,Robots!Q31,"")
D32: 3 | Q32: =IF(Robots!Q32<>0,Robots!Q32,"")
D33: 4 | Q33: =IF(Robots!Q33<>0,Robots!Q33,"")
D34: 5 | Q34: =IF(Robots!Q34<>0,Robots!Q34,"")
D35: 6 | Q35: =IF(Robots!Q35<>0,Robots!Q35,"")
D36: 7 | Q36: =IF(Robots!Q36<>0,Robots!Q36,"")
D37: 8 | Q37: =IF(Robots!Q37<>0,Robots!Q37,"")
D38: 9 | Q38: =IF(Robots!Q38<>0,Robots!Q38,"")
D39: 10 | Q39: =IF(Robots!Q39<>0,Robots!Q39,"")
D40: 11 | Q40: =IF(Robots!Q40<>0,Robots!Q40,"")
D41: 12 | Q41: =IF(Robots!Q41<>0,Robots!Q41,"")
D42: 13 | Q42: =IF(Robots!Q42<>0,Robots!Q42,"")
D43: 14 | Q43: =IF(Robots!Q43<>0,Robots!Q43,"")
...

Sheet ex ->

Sheet xxxxxxRxx
A1: Robot
I2: Robot inputs from PLC | L2: Robot outputs to PLC | Q2: Interlocks
A3: Folge | B3: Description | D3: Typ | E3: Description | G3: Release | H3: I/O | I3: Type | J3: Descrição | K3: I/O | L3: Type | M3: Description | N3: ST | O3: Device Nº | Q3: nº | R3: E/A
A4: 1 | B4: VW247-SC | D4: 1 | E4: 326-RDW | G4: 1 | H4: 80 | I4: LIB | J4: M. rodillos / Elevador | K4: 80 | L4: PF | M4: Rollenbahn / Heber | N4: 212330 | O4: 1
A5: 2 | B5: VW247-DC | D5: 2 | E5: 326-NAR | G5: 2 | H5: 79 | I5: LIB | J5: Soldadura | K5: 79 | L5: PF | M5: Werkzeug | N5: 212330 | O5: 2 | Q5: 1 | R5: 41
A6: 3 | B6: VW216 | D6: 2 | E6: 336-VLLL-VDR | G6: 3 | H6: 78 | K6: 78 | Q6: 2 | R6: 42
D7: 2 | E7: 336-VLLL-PSDR | G7: 4 | H7: 77 | K7: 77 | Q7: 3 | R7: 43
D8: 2 | E8: 336-MLL-VDR | G8: 5 | H8: 76 | K8: 76 | Q8: 4 | R8: 44
D9: 2 | E9: 336-MLL-PSDR | G9: 6 | H9: 75 | K9: 75 | Q9: 5 | R9: 45
G10: 7 | H10: 74 | K10: 74 | Q10: 6 | R10: 46
G11: 8 | H11: 73 | K11: 73 | Q11: 7 | R11: 47
G12: 9 | H12: 72 | K12: 72 | Q12: 8 | R12: 48
G13: 10 | H13: 71 | K13: 71 | Q13: 9 | R13: 49
G14: 11 | H14: 70 | K14: 70 | Q14: 10 | R14: 50
G15: 12 | H15: 69 | K15: 69 | Q15: 11 | R15: 51
G16: 13 | H16: 68 | K16: 68 | Q16: 12 | R16: 52
G17: 14 | H17: 67 | K17: 67 | Q17: 13 | R17: 53
G18: 15 | H18: 66 | K18: 66 | Q18: 14 | R18: 54
G19: 16 | H19: 65 | K19: 65 | Q19: 15 | R19: 55
G20: 17 | H20: 64 | K20: 64 | Q20: 16 | R20: 56
G21: 18 | H21: 63 | K21: 63
G22: 19 | H22: 62 | K22: 62
G23: 20 | H23: 61 | K23: 61 | Q23: Machine Safety
G24: 21 | H24: 60 | K24: 60 | Q24: =IF(Robots!Q24<>0,Robots!Q24,"")
G25: 22 | H25: 59 | K25: 59 | Q25: =IF(Robots!Q25<>0,Robots!Q25,"")
G26: 23 | H26: 58 | K26: 58 | Q26: =IF(Robots!Q26<>0,Robots!Q26,"")
G27: 24 | H27: 57 | K27: 57 | Q27: =IF(Robots!Q27<>0,Robots!Q27,"")
Q28: =IF(Robots!Q28<>0,Robots!Q28,"")
D29: FM | E29: Description | Q29: =IF(Robots!Q29<>0,Robots!Q29,"")
D30: 1 | E30: soldadura estacion 222340 | Q30: =IF(Robots!Q30<>0,Robots!Q30,"")
D31: 2 | Q31: =IF(Robots!Q31<>0,Robots!Q31,"")
D32: 3 | Q32: =IF(Robots!Q32<>0,Robots!Q32,"")
D33: 4 | Q33: =IF(Robots!Q33<>0,Robots!Q33,"")
D34: 5 | Q34: =IF(Robots!Q34<>0,Robots!Q34,"")
D35: 6 | Q35: =IF(Robots!Q35<>0,Robots!Q35,"")
D36: 7 | Q36: =IF(Robots!Q36<>0,Robots!Q36,"")
D37: 8 | Q37: =IF(Robots!Q37<>0,Robots!Q37,"")
D38: 9 | Q38: =IF(Robots!Q38<>0,Robots!Q38,"")
D39: 10 | Q39: =IF(Robots!Q39<>0,Robots!Q39,"")
D40: 11 | Q40: =IF(Robots!Q40<>0,Robots!Q40,"")
...

Sheet xxxxxxRxx (2)
A1: Robot
I2: Robot inputs from PLC | L2: Robot outputs to PLC | Q2: Interlocks
A3: Folge | B3: Description | D3: Typ | E3: Description | G3: Release | H3: I/O | I3: Type | J3: Descrição | K3: I/O | L3: Type | M3: Description | N3: ST | O3: Device Nº | Q3: nº | R3: E/A
A4: 1 | B4: VW247-SC | D4: 1 | E4: 326-RDW | G4: 1 | H4: 80 | I4: LIB | J4: busca | K4: 80 | L4: PF1 | M4: mov. Geral | N4: 112930BH1 | O4: 1
A5: 2 | B5: VW247-DC | D5: 2 | E5: 326-NAR | G5: 2 | H5: 79 | K5: 79 | Q5: 1 | R5: 41
A6: 3 | B6: VW216 | D6: 2 | E6: 336-VLLL-VDR | G6: 3 | H6: 78 | K6: 78 | L6: POS1 | M6: posição de pega | N6: 112930BH1 | O6: 1 | Q6: 2 | R6: 42
D7: 2 | E7: 336-VLLL-PSDR | G7: 4 | H7: 77 | I7: LIB | J7: busca | K7: 77 | L7: PF1 | M7: mov. Geral | N7: 112930BH2 | O7: 2 | Q7: 3 | R7: 43
D8: 2 | E8: 336-MLL-VDR | G8: 5 | H8: 76 | K8: 76 | Q8: 4 | R8: 44
D9: 2 | E9: 336-MLL-PSDR | G9: 6 | H9: 75 | K9: 75 | L9: POS1 | M9: posição de pega | N9: 112930BH2 | O9: 2 | Q9: 5 | R9: 45
G10: 7 | H10: 74 | I10: LIB | J10: deposita | K10: 74 | L10: PF1 | M10: mov. Geral | N10: 112933UQ1 | O10: 3 | Q10: 6 | R10: 46
G11: 8 | H11: 73 | I11: LIB | J11: busca | K11: 73 | L11: POS1 | M11: posição de depósito | N11: 112933UQ1 | O11: 3 | Q11: 7 | R11: 47
G12: 9 | H12: 72 | K12: 72 | L12: POS2 | M12: posição de pega | N12: 112933UQ1 | O12: 3 | Q12: 8 | R12: 48
G13: 10 | H13: 71 | I13: LIB | J13: deposita | K13: 71 | L13: PF1 | M13: mov. Geral | N13: 112933UQ2 | O13: 4 | Q13: 9 | R13: 49
G14: 11 | H14: 70 | I14: LIB | J14: busca | K14: 70 | L14: POS1 | M14: posição de depósito | N14: 112933UQ2 | O14: 4 | Q14: 10 | R14: 50
G15: 12 | H15: 69 | K15: 69 | L15: POS2 | M15: posição de pega | N15: 112933UQ2 | O15: 4 | Q15: 11 | R15: 51
G16: 13 | H16: 68 | I16: LIB | J16: deposita | K16: 68 | L16: PF1 | M16: mov. Geral | N16: 112933UQ3 | O16: 5 | Q16: 12 | R16: 52
G17: 14 | H17: 67 | I17: LIB | J17: busca | K17: 67 | L17: POS1 | M17: posição de depósito | N17: 112933UQ3 | O17: 5 | Q17: 13 | R17: 53
G18: 15 | H18: 66 | K18: 66 | L18: POS2 | M18: posição de pega | N18: 112933UQ3 | O18: 5 | Q18: 14 | R18: 54
G19: 16 | H19: 65 | I19: LIB | J19: deposita | K19: 65 | L19: PF1 | M19: mov. Geral | N19: 112933UQ4 | O19: 6 | Q19: 15 | R19: 55
G20: 17 | H20: 64 | I20: LIB | J20: busca | K20: 64 | L20: POS1 | M20: posição de depósito | N20: 112933UQ4 | O20: 6 | Q20: 16 | R20: 56
G21: 18 | H21: 63 | K21: 63 | L21: POS2 | M21: posição de pega | N21: 112933UQ4 | O21: 6
G22: 19 | H22: 62 | I22: LIB | J22: deposita | K22: 62 | L22: PF1 | M22: mov. Geral | N22: 112935V01 | O22: 7
G23: 20 | H23: 61 | J23: Eliminado sinal (Não necessário) | K23: 61 | M23: Eliminado sinal (Não necessário) | Q23: Machine Safety
G24: 21 | H24: 60 | K24: 60 | L24: POS1 | M24: posição de depósito | N24: 112935V01 | O24: 7 | Q24: =IF(Robots!Q24<>0,Robots!Q24,"")
G25: 22 | H25: 59 | I25: LIB | J25: cola | K25: 59 | Q25: =IF(Robots!Q25<>0,Robots!Q25,"")
G26: 23 | H26: 58 | K26: 58 | Q26: =IF(Robots!Q26<>0,Robots!Q26,"")
G27: 24 | H27: 57 | K27: 57 | Q27: =IF(Robots!Q27<>0,Robots!Q27,"")
G28: 25 | H28: 224 | I28: KT | J28: 112930BH1 ocupada 1 | K28: 224 | N28: 112930BH1 | O28: 1 | Q28: =IF(Robots!Q28<>0,Robots!Q28,"")
D29: FM | E29: Description | G29: 26 | H29: 223 | I29: /KT | J29: 112930BH1 livre 1 | K29: 223 | N29: 112930BH1 | O29: 1 | Q29: =IF(Robots!Q29<>0,Robots!Q29,"")
D30: 1 | E30: soldadura estacion 222340 | G30: 27 | H30: 222 | I30: KT | J30: 112930BH1 ocupada 2 | K30: 222 | N30: 112930BH1 | O30: 1 | Q30: =IF(Robots!Q30<>0,Robots!Q30,"")
D31: 2 | G31: 28 | H31: 221 | I31: /KT | J31: 112930BH1 livre 2 | K31: 221 | N31: 112930BH1 | O31: 1 | Q31: =IF(Robots!Q31<>0,Robots!Q31,"")
D32: 3 | G32: 29 | H32: 220 | I32: KT | J32: 112930BH1 ocupada 3 | K32: 220 | N32: 112930BH1 | O32: 1 | Q32: =IF(Robots!Q32<>0,Robots!Q32,"")
D33: 4 | G33: 30 | H33: 219 | I33: /KT | J33: 112930BH1 livre 3 | K33: 219 | N33: 112930BH1 | O33: 1 | Q33: =IF(Robots!Q33<>0,Robots!Q33,"")
D34: 5 | G34: 31 | H34: 218 | I34: KT | J34: 112930BH2 ocupada 1 | K34: 218 | N34: 112930BH2 | O34: 2 | Q34: =IF(Robots!Q34<>0,Robots!Q34,"")
D35: 6 | G35: 32 | H35: 217 | I35: /KT | J35: 112930BH2 livre 1 | K35: 217 | N35: 112930BH2 | O35: 2 | Q35: =IF(Robots!Q35<>0,Robots!Q35,"")
D36: 7 | G36: 33 | H36: 216 | I36: KT | J36: 112930BH2 ocupada 2 | K36: 208 | N36: 112930BH2 | O36: 2 | Q36: =IF(Robots!Q36<>0,Robots!Q36,"")
D37: 8 | G37: 34 | H37: 215 | I37: /KT | J37: 112930BH2 livre 2 | K37: 207 | N37: 112930BH2 | O37: 2 | Q37: =IF(Robots!Q37<>0,Robots!Q37,"")
D38: 9 | G38: 35 | H38: 214 | I38: KT | J38: 112930BH2 ocupada 3 | K38: 206 | N38: 112930BH2 | O38: 2 | Q38: =IF(Robots!Q38<>0,Robots!Q38,"")
D39: 10 | G39: 36 | H39: 213 | I39: /KT | J39: 112930BH2 livre 3 | K39: 205 | N39: 112930BH2 | O39: 2 | Q39: =IF(Robots!Q39<>0,Robots!Q39,"")
D40: 11 | G40: 37 | H40: 212 | I40: KT | J40: 112935V01 ocupada | K40: 204 | N40: 112935V01 | O40: 7 | Q40: =IF(Robots!Q40<>0,Robots!Q40,"")
...
